[27-May-23 05:39:34 - INFO] - bot - Bot Running..!

Created by 
https://t.me/CodeXBotz
[27-May-23 05:40:03 - ERROR] - pyrogram.dispatcher - bad auth : authentication failed, full error: {'ok': 0, 'errmsg': 'bad auth : authentication failed', 'code': 8000, 'codeName': 'AtlasError'}
Traceback (most recent call last):
  File "C:\Users\Kartik\AppData\Local\Programs\Python\Python310\lib\site-packages\pyrogram\dispatcher.py", line 240, in handler_worker
    await handler.callback(self.client, *args)
  File "C:\Users\Kartik\AppData\Local\Programs\Python\Python310\lib\site-packages\pyromod\listen\listen.py", line 93, in resolve_listener
    await self.user_callback(client, message, *args)
  File "d:\Others\anime5-main\anime5-main\plugins\start.py", line 24, in start_command
    if not await present_user(id):
  File "d:\Others\anime5-main\anime5-main\database\database.py", line 19, in present_user
    found = user_data.find_one({'_id': user_id})
  File "C:\Users\Kartik\AppData\Local\Programs\Python\Python310\lib\site-packages\pymongo\collection.py", line 1459, in find_one
    for result in cursor.limit(-1):
  File "C:\Users\Kartik\AppData\Local\Programs\Python\Python310\lib\site-packages\pymongo\cursor.py", line 1248, in next
    if len(self.__data) or self._refresh():
  File "C:\Users\Kartik\AppData\Local\Programs\Python\Python310\lib\site-packages\pymongo\cursor.py", line 1165, in _refresh
    self.__send_message(q)
  File "C:\Users\Kartik\AppData\Local\Programs\Python\Python310\lib\site-packages\pymongo\cursor.py", line 1052, in __send_message
    response = client._run_operation(
  File "C:\Users\Kartik\AppData\Local\Programs\Python\Python310\lib\site-packages\pymongo\_csot.py", line 105, in csot_wrapper
    return func(self, *args, **kwargs)
  File "C:\Users\Kartik\AppData\Local\Programs\Python\Python310\lib\site-packages\pymongo\mongo_client.py", line 1330, in _run_operation
    return self._retryable_read(
  File "C:\Users\Kartik\AppData\Local\Programs\Python\Python310\lib\site-packages\pymongo\_csot.py", line 105, in csot_wrapper
    return func(self, *args, **kwargs)
  File "C:\Users\Kartik\AppData\Local\Programs\Python\Python310\lib\site-packages\pymongo\mongo_client.py", line 1442, in _retryable_read
    with self._socket_from_server(read_pref, server, session) as (sock_info, read_pref):
  File "C:\Users\Kartik\AppData\Local\Programs\Python\Python310\lib\contextlib.py", line 135, in __enter__
    return next(self.gen)
  File "C:\Users\Kartik\AppData\Local\Programs\Python\Python310\lib\site-packages\pymongo\mongo_client.py", line 1282, in _socket_from_server
    with self._get_socket(server, session) as sock_info:
  File "C:\Users\Kartik\AppData\Local\Programs\Python\Python310\lib\contextlib.py", line 135, in __enter__
    return next(self.gen)
  File "C:\Users\Kartik\AppData\Local\Programs\Python\Python310\lib\site-packages\pymongo\mongo_client.py", line 1217, in _get_socket
    with server.get_socket(handler=err_handler) as sock_info:
  File "C:\Users\Kartik\AppData\Local\Programs\Python\Python310\lib\contextlib.py", line 135, in __enter__
    return next(self.gen)
  File "C:\Users\Kartik\AppData\Local\Programs\Python\Python310\lib\site-packages\pymongo\pool.py", line 1407, in get_socket
    sock_info = self._get_socket(handler=handler)
  File "C:\Users\Kartik\AppData\Local\Programs\Python\Python310\lib\site-packages\pymongo\pool.py", line 1520, in _get_socket
    sock_info = self.connect(handler=handler)
  File "C:\Users\Kartik\AppData\Local\Programs\Python\Python310\lib\site-packages\pymongo\pool.py", line 1378, in connect
    sock_info.authenticate()
  File "C:\Users\Kartik\AppData\Local\Programs\Python\Python310\lib\site-packages\pymongo\pool.py", line 870, in authenticate
    auth.authenticate(creds, self)
  File "C:\Users\Kartik\AppData\Local\Programs\Python\Python310\lib\site-packages\pymongo\auth.py", line 549, in authenticate
    auth_func(credentials, sock_info)
  File "C:\Users\Kartik\AppData\Local\Programs\Python\Python310\lib\site-packages\pymongo\auth.py", line 475, in _authenticate_default
    return _authenticate_scram(credentials, sock_info, "SCRAM-SHA-1")
  File "C:\Users\Kartik\AppData\Local\Programs\Python\Python310\lib\site-packages\pymongo\auth.py", line 241, in _authenticate_scram
    res = sock_info.command(source, cmd)
  File "C:\Users\Kartik\AppData\Local\Programs\Python\Python310\lib\site-packages\pymongo\pool.py", line 767, in command
    return command(
  File "C:\Users\Kartik\AppData\Local\Programs\Python\Python310\lib\site-packages\pymongo\network.py", line 166, in command
    helpers._check_command_response(
  File "C:\Users\Kartik\AppData\Local\Programs\Python\Python310\lib\site-packages\pymongo\helpers.py", line 181, in _check_command_response
    raise OperationFailure(errmsg, code, response, max_wire_version)
pymongo.errors.OperationFailure: bad auth : authentication failed, full error: {'ok': 0, 'errmsg': 'bad auth : authentication failed', 'code': 8000, 'codeName': 'AtlasError'}
[27-May-23 05:46:27 - INFO] - root - Stop signal received (SIGINT). Exiting...
[27-May-23 05:46:28 - INFO] - bot - Bot stopped.
[27-May-23 05:46:45 - INFO] - bot - Bot Running..!

Created by 
https://t.me/CodeXBotz
[27-May-23 05:57:07 - WARNING] - pyrogram.connection.connection - Unable to connect due to network issues: Connection timed out
